Workbook

Sheet 1-Input Data
A1: Area 1 - Extracted & Validated Data: Tata Steel Limited, Standalone (₹ crore) | F1: Colour legend
F2: Blue text | G2: Value extracted from the published results, or a stated assumption.
F3: Black text | G3: Formula computed on the same sheet.
A4: Profit & Loss | B4: FY 31.03.2026 | C4: FY 31.03.2025 | D4: Reported (validation) | F4: Yellow fill | G4: Assumption / policy parameter - not disclosed in the results, tune as needed.
A5: Revenue from operations | B5: 139720.22 | C5: 132516.66
A6: Other income | B6: 2165.7 | C6: 2246.9
A7: Total income | B7: =B5+B6 -> 141885.92 | C7: =C5+C6 -> 134763.56 | D7: 141885.92
A8: Total expenses | B8: 119433.96 | C8: 115142.68
A9: of which: Finance costs | B9: 5116.88 | C9: 4238.35
A10: of which: Depreciation & amortisation | B10: 7068.68 | C10: 6253.16
A11: Interest income and income from current investments (per cash flow) | B11: 1601.89 | C11: 1895.01
A12: Profit before exceptional items & tax | B12: =B7-B8 -> 22451.96 | C12: =C7-C8 -> 19620.88 | D12: 22451.96
A13: Exceptional items (net) | B13: -1098.86 | C13: -902.04
A14: Profit before tax | B14: =B12+B13 -> 21353.1 | C14: =C12+C13 -> 18718.84 | D14: 21353.1
A15: Total tax expense | B15: 5287.97 | C15: 4749.14
A16: Net profit for the period | B16: =B14-B15 -> 16065.13 | C16: =C14-C15 -> 13969.7 | D16: 16065.13
A17: Net finance charges (Finance costs − Interest income) | B17: =B9-B11 -> 3514.99 | C17: =C9-C11 -> 2343.34
A18: EBITDA (company definition: PBT + Net Finance Charges + D&A) | B18: =B12+B17+B10 -> 33035.63 | C18: =C12+C17+C10 -> 28217.38
A19: EBITDA margin (ties to reported operating EBITDA margin) | B19: =B18/B5 -> 0.2364413 | C19: =C18/C5 -> 0.21293458
A20: EBIT (company definition: row PBT + Net Finance Charges) | B20: =B12+B17 -> 25966.95 | C20: =C12+C17 -> 21964.22
A22: Balance Sheet | B22: FY 31.03.2026 | C22: FY 31.03.2025
A23: Property, plant & equipment (net) | B23: 109059.93 | C23: 93203.83
A24: Total assets | B24: 272747.42 | C24: 254132.74
A25: Total equity | B25: 135533.31 | C25: 126731.94
A26: Borrowings - non-current | B26: 50666.45 | C26: 51040.98
A27: Borrowings - current | B27: 14037.73 | C27: 8640.44
A28: Lease liabilities - non-current | B28: 3766.16 | C28: 3177.06
A29: Lease liabilities - current | B29: 578.93 | C29: 364.91
A30: Total debt (borrowings + lease liabilities) | B30: =SUM(B26:B29) -> 69049.27 | C30: =SUM(C26:C29) -> 63223.39
A31: Current investments | B31: 0.11 | C31: 0.12
A32: Cash & cash equivalents | B32: 2912.79 | C32: 3111.93
A33: Other balances with banks | B33: 191.6 | C33: 1032.69
A34: Net debt (company definition: row 30 − rows 31–33) | B34: =B30-B31-B32-B33 -> 65944.77 | C34: =C30-C31-C32-C33 -> 59078.65
A35: Current assets | B35: 33393.07 | C35: 33702.9
A36: Current liabilities | B36: 63732.79 | C36: 54482.92
A37: Total liabilities | B37: 137214.11 | C37: 127400.8
A39: Cash Flow (extracts) | B39: FY 31.03.2026 | C39: FY 31.03.2025
A40: Net cash from operating activities | B40: 31960.95 | C40: 23505.68
A41: Income taxes paid (net of refund) | B41: 4229.8 | C41: 2688.26
A42: Interest paid | B42: 6067.14 | C42: 5113.51
...

Sheet 2-Financial Analysis
A1: Area 2 - Financial Analysis & Interpretation | I1: Blue text | J1: Value extracted from the published results
I2: Black text | J2: Formula computed.
A3: Area 2 - Overall status | B3: =IF(AND(COUNTIF(H7:H13,"Pass")=ROWS(H7:H13),COUNTIF(H18:H26,"Pass")=ROWS(H18:H26)),"Approve","Reject") -> Approve | I3: Yellow fill | J3: Assumption / policy parameter, tune as needed.
A6: Statement | B6: Metric | C6: FY2026 | D6: FY2025 | E6: % Change | F6: Interpretation/Credit View | G6: Threshold | H6: Status | I6: Remarks | J6: Industry Threshold
A7: Income Statement | B7: Revenue | C7: 139720.22 | D7: 132516.66 | E7: =(C7-D7)/D7 -> 0.054359656 | F7: Growth in operating scale, positive for repayment capacity, Revenue Growth Range 5% to 10% is stable growth | G7: 0.05 | H7: =IF(E7>=5%,"Pass","Fail") -> Pass
A8: Income Statement | B8: EBITDA Margin % | C8: 23.64 | D8: 21.29 | E8: =(C8-D8)/D8 -> 0.11038046 | F8: Improving operating profitability strengthens debt servicing, EBITDA Margin 10%-15% is acceptable | G8: 0.1 | H8: =IF(E8>=10%,"Pass","Fail") -> Pass
A9: Income | B9: Net Profit | C9: 16065.13 | D9: 13969.7 | E9: =(C9-D9)/D9 -> 0.14999821 | F9: Higher earnings improve internal accruals, Net Profit 10%-15% is acceptable | G9: 0.1 | H9: =IF(E9>=10%,"Pass","Fail") -> Pass
A10: Balance Sheet | B10: Total Assets | C10: 272747.42 | D10: 254132.74 | E10: =(C10-D10)/D10 -> 0.073247863 | F10: Asset base expanded, supports business profile, asset base expansion above 5% is acceptable | G10: 0.05 | H10: =IF(E10>=5%,"Pass","Fail") -> Pass
A11: Balance Sheet | B11: Net Worth | C11: 132345.31 | D11: 123543.94 | E11: =(C11-D11)/D11 -> 0.071240807 | F11: Stronger capitalisation enhances resilience, Growing 5%-15% YoY means Improved financial strength, Positive | G11: 0.05 | H11: =IF(E11>=5%,"Pass","Fail") -> Pass
A12: Cash Flow | B12: Operating Cash Flow | C12: 31960.95 | D12: 23505.68 | E12: =(C12-D12)/D12 -> 0.35971178 | F12: Strong positive operating cash generation, Stable Positive OCF (±10% YoY), Sustainable operating cash generation, Satisfactory | G12: 0.1 | H12: =IF(E12>=10%,"Pass","Fail") -> Pass
A13: Cash Flow | B13: OCF to Debt | C13: =C12/'1-Input Data'!B30 -> 0.46287166 | D13: =D12/'1-Input Data'!C30 -> 0.37178772 | E13: =(C13-D13)/D13 -> 0.2449891 | F13: The OCF-to-debt ratio of approximately 46% is considered strong and reflects substantial debt repayment capacity. 20% - 35%Good | G13: 0.2 | H13: =IF(C13>=5%,"Pass","Fail") -> Pass
A14: Balance Sheet | B14: Total Debt | C14: 69049.27 | D14: 63223.39 | E14: =(C14-D14)/D14 -> 0.092147542 | G14: 0.15 | H14: =IF(C14>=5%,"Pass","Fail") -> Pass
A17: Ratio | B17: Formula | C17: FY2026 | D17: FY2025 | E17: % Change | F17: Interpretation | G17: Threshold | H17: Status | I17: Remarks | J17: Industry Threshold
A18: Debt-Equity | B18: Net Debt / Avg Equity | C18: 0.5 | D18: 0.44 | E18: =(C18-D18)/D18 -> 0.13636364 | F18: Key measure of leverage risk, Moderate leverage, slightly increased, 0.50x - 1.00x means Moderate leverage, Satisfactory | G18: 0.5 | H18: =IF(C18>=0.5,"Pass","Fail") -> Pass
A19: DSCR | B19: EBIT / (Interest+Principal) | C19: 2.85 | D19: 3.82 | E19: =(C19-D19)/D19 -> -0.2539267 | F19: Strong indicator of repayment ability, Above 1x, adequate debt servicing, 1.50x - 2.00x means Comfortable coverage, Good | G19: 1.5 | H19: =IF(C19>=1.5,"Pass","Fail") -> Pass
A20: Interest Service Coverage ratio | B20: EBIT / Net Finance Charges | C20: 8.08 | D20: 9.94 | E20: =(C20-D20)/D20 -> -0.18712274 | F20: Low default risk from interest burden, > 8.0x means Very strong coverage, 1.5x - 3.0x means Adequate coverage - Fair, 3.0x - 5.0x means Comfortable coverage - Good | G20: 3 | H20: =IF(C20>=3,"Pass","Fail") -> Pass
A21: Current Ratio | B21: Current Assets / Current Liabilities | C21: 0.58 | D21: 0.69 | E21: =(C21-D21)/D21 -> -0.15942029 | F21: Liquidity constraint but common in steel sector, Below 1, negative working capital, < 0.75x means Significant liquidity pressure - High Risk, 1.50x - 2.00x means Strong liquidity - Strong, 1.25x - 1.50x means Comfortable liquidity - Good | G21: 0.5 | H21: =IF(C21>=0.5,"Pass","Fail") -> Pass | I21: Current Ratio of 0.58x indicates a constrained liquidity position and negative working capital, however, this is relatively common in the steel industry, where companies benefit from strong supplier credit, efficient inventory turnover, and rapid receivable collections. The liquidity risk is partially mitigated by Tata Steel's strong operating cash flows and debt servicing capability | J21: 1.25
A22: Debt/Assets | B22: Total Debt / Total Assets | C22: 0.25 | D22: 0.25 | E22: =(C22-D22)/D22 -> 0 | F22: Shows asset protection for lenders, Stable leverage profile, < 0.20x means Very low leverage - Very Strong, 0.20x - 0.40x means Conservative leverage - Strong, 0.40x - 0.60x means Moderate leverage - Satisfactory | G22: 0.6 | H22: =IF(C22<0.6,"Pass","Fail") -> Pass
A23: Debtors Days | B23: Avg Receivables / Sales *365 | C23: 4 | D23: 4 | E23: =(C23-D23)/D23 -> 0 | F23: Supports liquidity, Very fast collection cycle, < 30 days means Excellent collections - Very Strong, 60 - 90 days means Acceptable collections - Satisfactory | G23: 30 | H23: =IF(C23<30,"Pass","Fail") -> Pass
A24: Inventory Days | B24: Avg Inventory / Cost of Sales *365 | C24: 62 | D24: 67 | E24: =(C24-D24)/D24 -> -0.074626866 | F24: Reduces working capital pressure, Improved inventory efficiency, < 30 days means Very efficient inventory management - Very Strong, 30 - 60 days means Good inventory turnover - Strong, 60 - 90 days means Acceptable inventory holding - Satisfactory | G24: 90 | H24: =IF(C24<90,"Pass","Fail") -> Pass
A25: EBITDA Margin % | B25: EBITDA / Revenue | C25: 23.64 | D25: 21.29 | E25: =(C25-D25)/D25 -> 0.11038046 | F25: Higher cash generation capacity, Margins improved, 15% - 20% means Healthy profitability - Good, 20% - 25% means Strong operating performance - Strong | G25: 15 | H25: =IF(C25>15,"Pass","Fail") -> Pass
A26: Net Profit Margin % | B26: PAT / Revenue | C26: 11.5 | D26: 10.54 | E26: =(C26-D26)/D26 -> 0.091081594 | F26: Supports internal debt repayment, Improved profitability, 10% - 15% means Healthy profitability - Good, 2% - 5% means Low profitability - Weak | G26: 10 | H26: =IF(C26>10,"Pass","Fail") -> Pass

Sheet Sheet1
J2: Step | K2: What happens | M2: Rule
J3: 1 | K3: Engine computes DSCR, Debt-to-Equity, ICR, Current Ratio and Debt/EBITDA from the signed-off Area 1 data. | M3: DSCR should be above minimum threshold (1.25x)
J4: 2 | K4: Each ratio is compared to its threshold, with the industry overlay applied (a manufacturing borrower is judged against manufacturing bands). | M4: Debt-to-Equity = Total Debt / Net Worth. should be under minimum threshold.
J5: 3 | K5: Trend rules run across the 3-year lines; each green flag returns YES/NO; all four YES = 'Positive trend'. | M5: Interest Coverage Ratio = EBIT / Interest Expense. Should be above minimum threshold
J6: 4 | K6: The stress case reruns DSCR with the stressed inputs; PASS requires stressed DSCR ≥ 1.25x. | M6: Current Ratio = Current Assets / Current Liabilities
J7: 5 | K7: Results go to the ratio dashboard (pass/watch/fail colouring) and to the narrative layer, which drafts the interpretation for the analyst to edit. | M7: (Short Term + Long Term Debt) / EBITDA (2–3x moderate, 4–5x risky)
M8: Trend Analysis: revenue growth rate should be above minimum threshold (e.g. ≥ 5% each of last 2 years)
M9: Trend Analysis: Debt lower each year-end
M10: Trend Analysis: Operating Cash Flow positive all 3 years
M11: qualitative factors such as management quality, industry outlook left with the analyst. The system covers only the quantitative layer.

Sheet 3-Risk Scoring
A1: Area 3 - Risk Scoring | G1: Blue text | H1: Value extracted from the published results
G2: Black text | H2: Formula computed.
A3: Score | B3: Definition | C3: Risk Interpretation | G3: Yellow fill | H3: Assumption / policy parameter, tune as needed.
A4: 5 | B4: Excellent | C4: Very Low Risk
A5: 4 | B5: Good | C5: Low Risk
A6: 3 | B6: Average | C6: Moderate Risk
A7: 2 | B7: Weak | C7: Elevated Risk
A8: 1 | B8: Poor | C8: High Risk
A10: Area 3 - Overall status | B10: =D24 -> Low Risk
A12: Parameter | B12: Weight % | C12: Score (1-5) | D12: Weighted Score | E12: Formula/Basis | F12: Interpretation | G12: Credit Review Contribution
A13: Financial Strength | B13: 25 | C13: =F35 -> 4.15 | D13: =(B13*C13)/100 -> 1.0375 | E13: Profitability, Net Worth Growth, OCF | F13: Strong earnings, Net Profit growth 15%, net worth growth 7.1%, OCF up 36% | G13: Primary indicator of repayment capacity
A14: Industry Risk | B14: 15 | C14: 3 | D14: =(B14*C14)/100 -> 0.45 | E14: Steel industry cyclicality | F14: Moderate risk due to commodity price cycles | G14: Industry stability affects future cash flows
A15: Management Quality | B15: 15 | C15: 4 | D15: =(B15*C15)/100 -> 0.6 | E15: Tata Group governance, market position | F15: Experienced management and strong governance | G15: Supports strategic execution and lender confidence
A16: Leverage | B16: 15 | C16: 4 | D16: =(B16*C16)/100 -> 0.6 | E16: Debt/Equity 0.50x, Debt/Assets 0.25x | F16: Conservative leverage profile | G16: Measures solvency and financial flexibility
A17: Liquidity | B17: 10 | C17: 2 | D17: =(B17*C17)/100 -> 0.2 | E17: Current Ratio 0.58x | F17: Weak liquidity but mitigated by strong operating cash flows | G17: Assesses short-term repayment ability
A18: Debt Service Capacity | B18: 10 | C18: 4 | D18: =(B18*C18)/100 -> 0.4 | E18: DSCR 2.85x, ICR 8.08x | F18: Strong debt servicing capability | G18: Key repayment-risk metric
A19: Collateral/Asset Coverage | B19: 5 | C19: 5 | D19: =(B19*C19)/100 -> 0.25 | E19: Net Worth 132,345 Cr, Total Assets 272,747 Cr | F19: Large asset base and equity cushion | G19: Provides lender recovery support
A20: Business Position | B20: 5 | C20: 5 | D20: =(B20*C20)/100 -> 0.25 | E20: Market leadership and diversification | F20: Strong competitive position | G20: Reduces business risk
A21: Total Weight | B21: =SUM(B13:B20) -> 100
A23: Total Weighted Score | D23: =SUM(D13:D20) -> 3.7875
A24: Risk Grade | D24: =INDEX($C$4:$C$8,MATCH(ROUND(D23,0),$A$4:$A$8,0)) -> Low Risk
A28: Financial Strength Scoring - FY 31.03.2026
A29: Metric | B29: Value | C29: Policy band coded (1 = weakest, 5 = strongest) | D29: Score | E29: Weight | F29: Contribution
A30: DSCR (reported) | B30: ='2-Financial Analysis'!C19 -> 2.85 | C30: ≥2.0x→5, 1.5–2.0x→4, 1.25–1.5x→3, 1.0–1.25x→2, <1.0x→1 | D30: =IF(B30>=2,5,IF(B30>=1.5,4,IF(B30>=1.25,3,IF(B30>=1,2,1)))) -> 5 | E30: 0.35 | F30: =D30*E30 -> 1.75
A31: ISCR (reported) | B31: ='2-Financial Analysis'!C20 -> 8.08 | C31: ≥3x→5, 2–3x→3, 1–2x→2, <1x→1 | D31: =IF(B31>=3,5,IF(B31>=2,3,IF(B31>=1,2,1))) -> 5 | E31: 0.25 | F31: =D31*E31 -> 1.25
A32: Current Ratio (reported) | B32: ='2-Financial Analysis'!C21 -> 0.58 | C32: ≥1.5→5, 1.2–1.5→3, 1.0–1.2→2, <1.0→1 | D32: =IF(B32>=1.5,5,IF(B32>=1.2,3,IF(B32>=1,2,1))) -> 1 | E32: 0.15 | F32: =D32*E32 -> 0.15
A33: Debt-to-Equity (reported basis) | B33: ='2-Financial Analysis'!C18 -> 0.5 | C33: ≤1.0x→4, 1–2x→3, 2–3x→2, >3x→1 | D33: =IF(B33<=1,4,IF(B33<=2,3,IF(B33<=3,2,1))) -> 4 | E33: 0.25 | F33: =D33*E33 -> 1
A35: Weighted score | C35: Sum of (component score × weight), weights must total 100% | E35: =SUM(E30:E33) -> 1 | F35: =SUM(F30:F33) -> 4.15

Sheet 4-Covenants
A1: Area 4 - Covenant Monitoring | L1: Blue text | M1: Value extracted from the published results
L2: Black text | M2: Formula computed.
A3: Headroom % = (Actual−Threshold)/Threshold for minimum covenants, reversed for maximum. RAG: >20% Green; 5–20% Amber; <5% or breach Red. | L3: Yellow fill | M3: Assumption / policy parameter, tune as needed.
A10: Covenant | B10: Threshold | C10: Actual | D10: Headroom | E10: RAG status
A11: DSCR, reported basis (minimum) | B11: 1.5 | C11: ='2-Financial Analysis'!C19 -> 2.85 | D11: =(C11-B11)/B11 -> 0.9 | E11: =IF(D11>0.2,"GREEN",IF(D11>=0.05,"AMBER","RED")) -> GREEN
A12: ISCR, reported basis (minimum) | B12: 2 | C12: ='2-Financial Analysis'!C20 -> 8.08 | D12: =(C12-B12)/B12 -> 3.04 | E12: =IF(D12>0.2,"GREEN",IF(D12>=0.05,"AMBER","RED")) -> GREEN
D14: Overall Status | E14: =IF(COUNTIF(E11:E12,"AMBER")+COUNTIF(E11:E12,"RED")>0,"NOT PASS","PASS") -> PASS

Sheet 5-Collateral Assessment
A1: Area 5 - Collateral Assessment | F1: Blue text | G1: Value extracted from the published results
F2: Black text | G2: Formula computed.
A3: Collateral Type | B3: Typical Haircut | F3: Yellow fill | G3: Assumption / policy parameter, tune as needed.
A4: Cash & Bank Deposits | B4: 0%-10%
A5: Government Securities | B5: 5%-15%
A6: Listed Investments | B6: 20%-40%
A7: Trade Receivables | B7: 25%-50%
A8: Inventory | B8: 40%-60%
A9: Plant & Machinery | B9: 40%-60%
A10: Real Estate | B10: 25%-40%
A12: Area 5 - Overall status | B12: =D24 -> High collateral risk
A14: Collateral Type | B14: Book Value (Rs Cr) | C14: Haircut % | D14: Adjusted Value (Rs Cr) | E14: Liquidity | F14: Security Rank | G14: Assessment | H14: Credit Relevance
A15: Cash & Bank Balances | B15: 3104 | C15: 5 | D15: =B15*(1-C15/100) -> 2948.8 | E15: High | F15: Primary | G15: Excellent collateral | H15: Immediate repayment source
A16: Investments | B16: 94529 | C16: 30 | D16: =B16*(1-C16/100) -> 66170.3 | E16: Medium-High | F16: Primary | G16: Market value sensitive | H16: Strong secondary support
A17: Trade Receivables | B17: 1632 | C17: 25 | D17: =B17*(1-C17/100) -> 1224 | E17: Medium | F17: Primary | G17: Good quality receivables | H17: Supports working capital facilities
A18: Inventory | B18: 23059 | C18: 50 | D18: =B18*(1-C18/100) -> 11529.5 | E18: Medium | F18: Primary | G18: Subject to price volatility | H18: Moderate collateral support
A19: Property Plant & Equipment | B19: 109060 | C19: 45 | D19: =B19*(1-C19/100) -> 59983 | E19: Low | F19: Fixed Charge | G19: Large tangible asset base | H19: Strong recovery support
A21: Total Adjusted Collateral Value | D21: =SUM(D15:D19) -> 141855.6
A22: Assumed Debt Exposure (Rs Cr) | D22: ='1-Input Data'!B30 -> 69049.27
A23: Collateral Coverage Ratio | D23: =D21/D22 -> 2.0544113
A24: Collateral Rating | D24: =IF(D23>125,$C$28,IF(D23>=100,$C$29,$C$30)) -> High collateral risk
A27: Collateral Coverage Ratio | B27: Interpretation | C27: Credit View
A28: >125 | B28: Collateral value substantially exceeds the credit exposure. Provides a strong recovery cushion in a default scenario and reduces loss-given-default (LGD) | C28: Low collateral risk
A29: 100-125 | B29: Collateral adequately covers the outstanding exposure. Recovery prospects are reasonable, though the cushion against valuation fluctuations is limited | C29: Moderate collateral risk
A30: <100 | B30: Collateral value is insufficient to fully cover the credit exposure. Lenders may face recovery shortfalls in the event of default. Additional security, guarantees, or stronger financial covenants may be required. | C30: High collateral risk

Sheet 6-Limit Setting
A1: Area 6 - Proposed Loan Impact & Limit Recommendation (₹ crore) | H1: Blue text | I1: Value extracted from the published results
H2: Black text | I2: Formula computed.
A3: Proposed Facility | H3: Yellow fill | I3: Assumption / policy parameter, tune as needed.
A4: Term loan amount requested | B4: 5000
A5: Interest rate (p.a.) | B5: 0.08
A6: Tenor (years, equal annual instalments) | B6: 5
A7: Annual instalment (annuity) | B7: =-PMT(B5,B6,B4) -> 1252.2823
A9: Repayment (Amortization) Schedule
A10: Year | B10: Opening balance | C10: Interest (8%) | D10: Principal | E10: Closing balance
A11: 1 | B11: =B4 -> 5000 | C11: =B11*$B$5 -> 400 | D11: =$B$7-C11 -> 852.28227 | E11: =B11-D11 -> 4147.7177
A12: 2 | B12: =E11 -> 4147.7177 | C12: =B12*$B$5 -> 331.81742 | D12: =$B$7-C12 -> 920.46485 | E12: =B12-D12 -> 3227.2529
A13: 3 | B13: =E12 -> 3227.2529 | C13: =B13*$B$5 -> 258.18023 | D13: =$B$7-C13 -> 994.10204 | E13: =B13-D13 -> 2233.1508
A14: 4 | B14: =E13 -> 2233.1508 | C14: =B14*$B$5 -> 178.65207 | D14: =$B$7-C14 -> 1073.6302 | E14: =B14-D14 -> 1159.5206
A15: 5 | B15: =E14 -> 1159.5206 | C15: =B15*$B$5 -> 92.76165 | D15: =$B$7-C15 -> 1159.5206 | E15: =B15-D15 -> 0
A18: Position after assuming that the proposed loan has been disbursed
A19: Implied existing debt-service denominator (EBIT/reported DSCR) | B19: ='1-Input Data'!B20/'1-Input Data'!B49 -> 9111.2105
A20: New loan instalment | B20: =B7 -> 1252.2823
A21: Total pro-forma debt service | B21: =B19+B20 -> 10363.493 | C21: Interpretation:After the new facility, Company's estimated annual debt-servicing requirement increases from approximately 9,111 cr. to 10,363 cr.
A22: EBIT | B22: ='1-Input Data'!B20 -> 25966.95
A23: Pro-forma DSCR | B23: =B22/B21 -> 2.5056176
A24: Policy minimum DSCR | B24: 1.5
A25: Pro-forma DSCR status (≥ 1.5x) | B25: PASS
A26: Credit Conclusion - The 5,000 cr. loan appears serviceable on the workbook’s pro-forma assumptions.
A29: Debt Service Capacity
A30: Policy minimum DSCR | B30: 1.5
A31: Maximum serviceable total debt service | B31: =B22/B30 -> 17311.3
A32: Implied existing debt-service denominator (EBIT/reported DSCR) | B32: =B19 -> 9111.2105
A33: Available additional annual debt service | B33: =B31-B32 -> 8200.0895
A34: Capacity cap: max additional loan at 8% / 5 yrs | B34: =B33*(1-(1+B5)^-B6)/B5 -> 32740.58
A36: Limit Recommendation (MIN of caps)
A37: (a) Requested amount | B37: =B4 -> 5000
A38: (b) Capacity cap (from above) | B38: =B34 -> 32740.58
A39: Recommended limit = MIN(a, b) | B39: =MIN(B37:B38) -> 5000
A40: Conclusion | B40: =IF(B39=B4,"PASS") -> PASS

Sheet 7-Continuous Monitoring
A1: Area 7 - Continuous Monitoring & Early Warning Signals | F1: Blue text | G1: Value extracted from the published results
F2: Black text | G2: Formula computed.
A3: Trigger | B3: Threshold (configurable) | C3: Computed value | D3: Status | F3: Yellow fill | G3: Assumption / policy parameter, tune as needed.
A4: Revenue decline YoY | B4: -0.1 | C4: ='2-Financial Analysis'!E7 -> 0.054359656 | D4: =IF(C4>B4,"PASS","FAIL") -> PASS
A5: Total debt increase YoY | B5: 0.15 | C5: ='2-Financial Analysis'!E14 -> 0.092147542 | D5: =IF(C5<=B5,"PASS","FAIL") -> PASS
A6: Reported DSCR deterioration YoY | B6: -0.35 | C6: ='2-Financial Analysis'!E19 -> -0.2539267 | D6: =IF(C6>B6,"PASS","FAIL") -> PASS
A7: Any covenant on Amber/Red | B7: ≥ 1 → watch list | D7: =IF(COUNTIF('4-Covenants'!E11:E12,"AMBER")+COUNTIF('4-Covenants'!E11:E12,"RED")>0,"WATCH LIST","PASS") -> PASS
A8: External rating downgrade | B8: Any downgrade → watch list | C8: No Change | D8: PASS
A9: Adverse news / qualitative disclosure | B9: Material adverse item → Amber, analyst verifies | C9: No Change | D9: PASS
C10: Overall Status | D10: =IF(COUNTIF(D4:D9,"NOT PASS")>0,"NOT PASS","PASS") -> PASS

Sheet 8-Portfolio Monitoring
A1: Area 8 - Portfolio Monitoring | F1: Blue text | G1: Value extracted from the published results
F2: Black text | G2: Formula computed.
F3: Yellow fill | G3: Assumption / policy parameter, tune as needed.
A4: Area 8 - Overall status | B4: =IF(COUNTIF(C20:C22,"Low Risk")+COUNTIF(C20:C22,"Moderate Risk")>=2,"Approve","Reject") -> Approve
A6: Parameter | B6: Formula/Basis | C6: Value | D6: Assessment Range | E6: Interpretation
A7: Portfolio Segment | B7: Input value | C7: Manufacturing | D7: N/A | E7: Industry portfolio under review
A8: Total Portfolio Exposure (Rs Cr) | B8: Input value | C8: 100000 | D8: N/A | E8: Existing portfolio exposure
A9: Number of Accounts | B9: Input value | C9: 250 | D9: N/A | E9: Portfolio diversification measure
A10: Average Exposure per Account | B10: Portfolio Exposure / Accounts | C10: 400 | D10: Lower is better | E10: Measures concentration per account
A11: Proposed Loan Amount (Rs Cr) | B11: Input value | C11: 5000 | D11: N/A | E11: Requested exposure
A12: Borrower Concentration % | B12: Loan/Portfolio Exposure | C12: =C11/C8 -> 0.05 | D12: <5% Strong; 5-10% Moderate; >10% High | E12: Concentration risk indicator. The proposed exposure of ₹5,000 Cr represents 5.0% of the existing portfolio, indicating moderate concentration risk
A13: Gross NPL (Rs Cr) | B13: Input value | C13: 2000 | D13: N/A | E13: Non-performing exposure
A14: Gross NPL Ratio % | B14: NPL/Portfolio Exposure | C14: =C13/C8 -> 0.02 | D14: <2% Low; 2-5% Moderate; >5% High | E14: Asset quality indicator
A15: Portfolio Exposure Post Sanction | B15: Exposure+Loan | C15: =C8+C11 -> 105000 | D15: N/A | E15: Revised portfolio size
A16: Single Borrower Exposure % | B16: Loan/Post Exposure | C16: =C11/C15 -> 0.047619048 | D16: <5% Low; 5-10% Moderate; >10% High | E16: Borrower concentration after sanction
A19: Criteria | B19: Value | C19: Credit View
A20: Non Performing Loan% | B20: =C14 -> 0.02 | C20: =IF(B20<=2%,"Low Risk",IF(B20<5%,"Moderate Risk","High Risk")) -> Low Risk
A21: Borrower Concentration Risk | B21: =C12 -> 0.05 | C21: =IF(B21<5%,"Low Risk",IF(B21<=10%,"Moderate Risk","High Risk")) -> Moderate Risk
A22: Manufacturing Sector Exposure | B22: =C16 -> 0.047619048 | C22: =IF(B22<5%,"Low Risk",IF(B22<=10%,"Moderate Risk","High Risk")) -> Low Risk
A25: Scale
A26: Non Performing Loan% | B26: Portfolio Health | D26: Borrower Concentration Risk | E26: Interpretation | G26: Sector Concentration (Manufacturing) | H26: Interpretation
A27: <2% | B27: Low Risk | D27: <5% | E27: Low Risk | G27: <20% | H27: Low Risk
A28: 2%-5% | B28: Moderate | D28: 5%-10% | E28: Moderate | G28: 20%-30% | H28: Moderate
A29: >5% | B29: High Risk | D29: >10% | E29: High Risk | G29: >30% | H29: High Risk

Sheet 9 - Credit Memo
A1: Area 9 - Credit Memo: Summary
A3: Area 2 - Financial Analysis & Interpretation | B3: Status
A4: Credit Opinion: Stable to Positive Revenue growth, improved EBITDA margins and stronger operating cash flow support credit quality. Net worth increased and debt/assets remained stable. Key concern remains weak current ratio and negative working capital. Interest coverage (8.08x) and DSCR (2.85x) indicate comfortable debt servicing capacity. Overall assessment: Strong investment-grade operating profile with adequate liquidity and robust cash generation." | B4: ='2-Financial Analysis'!B3 -> Approve
A7: Area 3 - Risk Scoring | B7: Status
A8: Overall Weighted Score: 3.8/5.00. Recommended Credit View: MODERATE TO LOW RISK. Strengths include strong profitability, cash flow generation, asset coverage and debt servicing metrics. Key risk factor is weak current ratio and cyclical steel industry exposure. Overall credit profile remains acceptable for lending subject to normal monitoring. | B8: ='3-Risk Scoring'!B10 -> Low Risk
A11: Area 4 - Covenant Monitoring | B11: Status
A12: The reported financial covenants remain comfortably compliant. DSCR of 2.85x provides 90% headroom over the 1.5x minimum, while ISCR of 8.08x provides 304% headroom over the 2.00x minimum; both are currently rated Green. | B12: ='4-Covenants'!E14 -> PASS
A15: Area 5 - Collateral Assessment Summary | B15: Status
A16: Tata Steel benefits from substantial collateral support from PPE, investments, inventory and receivables. After applying conservative haircuts, adjusted collateral value provides strong coverage to estimated debt obligations. Large asset base and equity support lender recovery prospects. | B16: ='5-Collateral Assessment'!B12 -> High collateral risk
A19: Area 6 - Proposed Loan Impact & Limit Recommendation (₹ crore) | B19: Status
A20: The proposed 5,000cr. term loan is serviceable under the model assumptions. The new annual instalment is approximately 1,252cr., increasing estimated annual debt service from 9,111cr. to 10,363cr. Pro-forma DSCR is estimated at 2.51x, above the 1.50x policy minimum. At the same minimum DSCR, available additional annual debt-service capacity is approximately 8,200cr., applying the five-year annuity factor at 8% produces a capacity cap of approximately 32,741cr. Since the requested amount of 5,000cr. is below this cap, the recommended limit is 5,000cr. | B20: ='6-Limit Setting'!B40 -> PASS
A23: Area 7 - Continuous Monitoring | B23: Status
A24: All continuous-monitoring indicators are within the defined thresholds. Revenue grew by 5.4% against a trigger of more than 10% decline, total debt increased by 9.2% against the permitted threshold of 15%, and DSCR deterioration of 25.4% remained within the 35% threshold. No covenant is currently Amber or Red. Assuming no external credit-rating downgrade or adverse news, the overall continuous-monitoring status is PASS. | B24: ='7-Continuous Monitoring'!D10 -> PASS
A27: Area 8 - Portfolio Monitoring | B27: Status
A28: The proposed Rs 5,000 crore exposure represents a moderate concentration level relative to the existing manufacturing portfolio. Asset quality remains acceptable with a moderate NPL ratio. Overall portfolio capacity appears adequate to accommodate the proposed facility, subject to ongoing monitoring of concentration and sector risk. | B28: ='8-Portfolio Monitoring'!B4 -> Approve

Sheet Sheet2
C3: Business Analysis
C4: Limit setting of consortium banks - basis repayment capcbility
C5: Banking Analysis - monitor the txn of client
C6: Review Company abckground
